Workbook
Name Confidence_Interval: 'Value at Risk (VaR)'!$AB$23
Name Covariance: '[1]Value at Risk (VaR)'!$V$27
Name Covariance: 'Value at Risk (VaR)'!$V$27
Name Days: '[1]Value at Risk (VaR)'!$AB$21
Name Days: 'Value at Risk (VaR)'!$AB$21
Name Expected_Return: '[1]Value at Risk (VaR)'!$V$21
Name Expected_Return: 'Value at Risk (VaR)'!$V$21
Name Portfolio_St._dev.: '[1]Value at Risk (VaR)'!$Y$26
Name Portfolio_St._dev.: 'Value at Risk (VaR)'!$Y$26
Name Portfolio_Value: '[1]Value at Risk (VaR)'!$Y$21
Name Portfolio_Value: 'Value at Risk (VaR)'!$Y$21
Name Portfolio_Variance: 'Value at Risk (VaR)'!$Y$25
Name St._dev.: '[1]Value at Risk (VaR)'!$V$26
Name St._dev.: 'Value at Risk (VaR)'!$V$26
Name St._dev._nifty: '[1]Value at Risk (VaR)'!$V$22
Name St._dev._nifty: 'Value at Risk (VaR)'!$V$22
Name UPDATE: '[2]Data Sheet'!$E$1
Name UPDATE: '[1]Data Sheet'!$E$1
Name UPDATE: 'Data Sheet'!$E$1
Name Weight_of_Nifty_50: '[1]Value at Risk (VaR)'!$Y$22
Name Weight_of_Nifty_50: 'Value at Risk (VaR)'!$Y$22
Name Weight_of_Tata_Power_Ltd.: '[1]Value at Risk (VaR)'!$Y$23
Name Weight_of_Tata_Power_Ltd.: 'Value at Risk (VaR)'!$Y$23
Name Z.score: '[1]Value at Risk (VaR)'!$AB$24
Name Z.score: 'Value at Risk (VaR)'!$AB$24

Sheet Profit & Loss
A1: ='Data Sheet'!B1 -> TATA POWER COMPANY LTD | H1: =UPDATE | M1: SCREENER.IN
A3: Narration | B3: ='Data Sheet'!B16 -> 42825 | C3: ='Data Sheet'!C16 -> 43190 | D3: ='Data Sheet'!D16 -> 43555 | E3: ='Data Sheet'!E16 -> 43921 | F3: ='Data Sheet'!F16 -> 44286 | G3: ='Data Sheet'!G16 -> 44651 | H3: ='Data Sheet'!H16 -> 45016 | I3: ='Data Sheet'!I16 -> 45382 | ... K3: ='Data Sheet'!K16 -> 46112 | L3: Trailing | M3: Best Case | N3: Worst Case
A4: Sales | B4: ='Data Sheet'!B17 -> 27587.59 | C4: ='Data Sheet'!C17 -> 26840.27 | D4: ='Data Sheet'!D17 -> 29881.06 | E4: ='Data Sheet'!E17 -> 29136.37 | F4: ='Data Sheet'!F17 -> 32703.31 | G4: ='Data Sheet'!G17 -> 42815.67 | H4: ='Data Sheet'!H17 -> 55109.08 | I4: ='Data Sheet'!I17 -> 61448.9 | ... K4: ='Data Sheet'!K17 -> 62428.59 | L4: =SUM(Quarters!H4:K4) -> 62428.59 | M4: =$K4+M23*K4 -> 65078.417 | N4: =$K4+N23*L4 -> 62428.59
A5: Expenses | B5: =SUM('Data Sheet'!B18,'Data Sheet'!B20:B24, -1*'Data Sheet'!B19) -> 22114.32 | C5: =SUM('Data Sheet'!C18,'Data Sheet'!C20:C24, -1*'Data Sheet'!C19) -> 21833.12 | D5: =SUM('Data Sheet'!D18,'Data Sheet'!D20:D24, -1*'Data Sheet'!D19) -> 23449.05 | E5: =SUM('Data Sheet'!E18,'Data Sheet'!E20:E24, -1*'Data Sheet'!E19) -> 22331.3 | F5: =SUM('Data Sheet'!F18,'Data Sheet'!F20:F24, -1*'Data Sheet'!F19) -> 25782.41 | G5: =SUM('Data Sheet'!G18,'Data Sheet'!G20:G24, -1*'Data Sheet'!G19) -> 35784.78 | H5: =SUM('Data Sheet'!H18,'Data Sheet'!H20:H24, -1*'Data Sheet'!H19) -> 47381.32 | I5: =SUM('Data Sheet'!I18,'Data Sheet'!I20:I24, -1*'Data Sheet'!I19) -> 50713.62 | ... K5: =SUM('Data Sheet'!K18,'Data Sheet'!K20:K24, -1*'Data Sheet'!K19) -> 49157.32 | L5: =SUM(Quarters!H5:K5) -> 49907.37 | M5: =M4-M6 -> 52025.725 | N5: =N4-N6 -> 51360.879
A6: Operating Profit | B6: =B4-B5 -> 5473.27 | C6: =C4-C5 -> 5007.15 | D6: =D4-D5 -> 6432.01 | E6: =E4-E5 -> 6805.07 | F6: =F4-F5 -> 6920.9 | G6: =G4-G5 -> 7030.89 | H6: =H4-H5 -> 7727.76 | I6: =I4-I5 -> 10735.28 | ... K6: =K4-K5 -> 13271.27 | L6: =SUM(Quarters!H6:K6) -> 12521.22 | M6: =M4*M24 -> 13052.692 | N6: =N4*N24 -> 11067.711
A7: Other Income | B7: ='Data Sheet'!B25 -> 1297.37 | C7: ='Data Sheet'!C25 -> 3873.32 | D7: ='Data Sheet'!D25 -> 3824.37 | E7: ='Data Sheet'!E25 -> 2280.15 | F7: ='Data Sheet'!F25 -> 1774.96 | G7: ='Data Sheet'!G25 -> 2485.5 | H7: ='Data Sheet'!H25 -> 5540.09 | I7: ='Data Sheet'!I25 -> 3416.33 | ... K7: ='Data Sheet'!K25 -> 3432.6 | L7: =SUM(Quarters!H7:K7) -> 4182.65 | M7: 0 | N7: 0
A8: Depreciation | B8: ='Data Sheet'!B26 -> 1955.59 | C8: ='Data Sheet'!C26 -> 2346.17 | D8: ='Data Sheet'!D26 -> 2393.13 | E8: ='Data Sheet'!E26 -> 2633.56 | F8: ='Data Sheet'!F26 -> 2744.94 | G8: ='Data Sheet'!G26 -> 3122.2 | H8: ='Data Sheet'!H26 -> 3439.2 | I8: ='Data Sheet'!I26 -> 3786.37 | ... K8: ='Data Sheet'!K26 -> 4811.09 | L8: =SUM(Quarters!H8:K8) -> 4811.09 | M8: =+$L8 -> 4811.09 | N8: =+$L8 -> 4811.09
A9: Interest | B9: ='Data Sheet'!B27 -> 3364.96 | C9: ='Data Sheet'!C27 -> 3761.48 | D9: ='Data Sheet'!D27 -> 4170 | E9: ='Data Sheet'!E27 -> 4493.73 | F9: ='Data Sheet'!F27 -> 4010.39 | G9: ='Data Sheet'!G27 -> 3859.02 | H9: ='Data Sheet'!H27 -> 4371.65 | I9: ='Data Sheet'!I27 -> 4633.22 | ... K9: ='Data Sheet'!K27 -> 5256.79 | L9: =SUM(Quarters!H9:K9) -> 5256.79 | M9: =+$L9 -> 5256.79 | N9: =+$L9 -> 5256.79
A10: Profit before tax | B10: ='Data Sheet'!B28 -> 1450.09 | C10: ='Data Sheet'!C28 -> 2772.82 | D10: ='Data Sheet'!D28 -> 3693.25 | E10: ='Data Sheet'!E28 -> 1957.93 | F10: ='Data Sheet'!F28 -> 1940.53 | G10: ='Data Sheet'!G28 -> 2535.17 | H10: ='Data Sheet'!H28 -> 5457 | I10: ='Data Sheet'!I28 -> 5732.02 | ... K10: ='Data Sheet'!K28 -> 6635.99 | L10: =SUM(Quarters!H10:K10) -> 6635.99 | M10: =M6+M7-SUM(M8:M9) -> 2984.8123 | N10: =N6+N7-SUM(N8:N9) -> 999.83127
A11: Tax | B11: ='Data Sheet'!B29 -> 350.46 | C11: ='Data Sheet'!C29 -> 161.97 | D11: ='Data Sheet'!D29 -> 1087.59 | E11: ='Data Sheet'!E29 -> 641.49 | F11: ='Data Sheet'!F29 -> 501.88 | G11: ='Data Sheet'!G29 -> 379.56 | H11: ='Data Sheet'!H29 -> 1647.33 | I11: ='Data Sheet'!I29 -> 1451.92 | ... K11: ='Data Sheet'!K29 -> 1518.43 | L11: =SUM(Quarters!H11:K11) -> 1518.43 | M11: =IF($L10>0,$L11/$L10,0) -> 0.2288174 | N11: =IF($L10>0,$L11/$L10,0) -> 0.2288174
A12: Net profit | B12: ='Data Sheet'!B30 -> 896.55 | C12: ='Data Sheet'!C30 -> 2408.3 | D12: ='Data Sheet'!D30 -> 2356.19 | E12: ='Data Sheet'!E30 -> 1017.38 | F12: ='Data Sheet'!F30 -> 1127.38 | G12: ='Data Sheet'!G30 -> 1741.46 | H12: ='Data Sheet'!H30 -> 3336.44 | I12: ='Data Sheet'!I30 -> 3696.25 | ... K12: ='Data Sheet'!K30 -> 3747.19 | L12: =SUM(Quarters!H12:K12) -> 3747.19 | M12: =M10-M11*M10 -> 2301.8353 | N12: =N10-N11*N10 -> 771.05248
A13: EPS | B13: =IF('Data Sheet'!B93>0,B12/'Data Sheet'!B93,0) -> 3.3146628 | C13: =IF('Data Sheet'!C93>0,C12/'Data Sheet'!C93,0) -> 8.9038007 | D13: =IF('Data Sheet'!D93>0,D12/'Data Sheet'!D93,0) -> 8.7111432 | E13: =IF('Data Sheet'!E93>0,E12/'Data Sheet'!E93,0) -> 3.7613872 | F13: =IF('Data Sheet'!F93>0,F12/'Data Sheet'!F93,0) -> 3.5282446 | G13: =IF('Data Sheet'!G93>0,G12/'Data Sheet'!G93,0) -> 5.4500673 | H13: =IF('Data Sheet'!H93>0,H12/'Data Sheet'!H93,0) -> 10.441711 | I13: =IF('Data Sheet'!I93>0,I12/'Data Sheet'!I93,0) -> 11.567771 | ... K13: =IF('Data Sheet'!K93>0,K12/'Data Sheet'!K93,0) -> 11.727193 | L13: =IF('Data Sheet'!$B6>0,'Profit & Loss'!L12/'Data Sheet'!$B6,0) -> 11.727048 | M13: =IF('Data Sheet'!$B6>0,'Profit & Loss'!M12/'Data Sheet'!$B6,0) -> 7.2037267 | N13: =IF('Data Sheet'!$B6>0,'Profit & Loss'!N12/'Data Sheet'!$B6,0) -> 2.4130533
A14: Price to earning | B14: =IF(B15>0,B15/B13,"") -> 27.257674 | C14: =IF(C15>0,C15/C13,"") -> 8.8726155 | D14: =IF(D15>0,D15/D13,"") -> 8.4719076 | E14: =IF(E15>0,E15/E13,"") -> 8.7334801 | F14: =IF(F15>0,F15/F13,"") -> 29.263844 | G14: =IF(G15>0,G15/G13,"") -> 43.78845 | H14: =IF(H15>0,H15/H13,"") -> 18.220194 | I14: =IF(I15>0,I15/I13,"") -> 34.077437 | ... K14: =IF(K15>0,K15/K13,"") -> 32.296731 | L14: =IF(L13>0,L15/L13,0) -> 34.309573 | M14: =M25 -> 34.309573 | N14: =N25 -> 25.045345
A15: Price | B15: ='Data Sheet'!B90 -> 90.35 | C15: ='Data Sheet'!C90 -> 79 | D15: ='Data Sheet'!D90 -> 73.8 | E15: ='Data Sheet'!E90 -> 32.85 | F15: ='Data Sheet'!F90 -> 103.25 | G15: ='Data Sheet'!G90 -> 238.65 | H15: ='Data Sheet'!H90 -> 190.25 | I15: ='Data Sheet'!I90 -> 394.2 | ... K15: ='Data Sheet'!K90 -> 378.75 | L15: ='Data Sheet'!B8 -> 402.35 | M15: =M13*M14 -> 247.15679 | N15: =N13*N14 -> 60.435752
A17: RATIOS:
A18: Dividend Payout | B18: =IF('Data Sheet'!B30>0, 'Data Sheet'!B31/'Data Sheet'!B30, 0) -> 0.39222575 | C18: =IF('Data Sheet'!C30>0, 'Data Sheet'!C31/'Data Sheet'!C30, 0) -> 0.14601586 | D18: =IF('Data Sheet'!D30>0, 'Data Sheet'!D31/'Data Sheet'!D30, 0) -> 0.14924518 | E18: =IF('Data Sheet'!E30>0, 'Data Sheet'!E31/'Data Sheet'!E30, 0) -> 0.4121174 | F18: =IF('Data Sheet'!F30>0, 'Data Sheet'!F31/'Data Sheet'!F30, 0) -> 0.43935496 | G18: =IF('Data Sheet'!G30>0, 'Data Sheet'!G31/'Data Sheet'!G30, 0) -> 0.3211271 | H18: =IF('Data Sheet'!H30>0, 'Data Sheet'!H31/'Data Sheet'!H30, 0) -> 0.19155747 | I18: =IF('Data Sheet'!I30>0, 'Data Sheet'!I31/'Data Sheet'!I30, 0) -> 0.17291038 | ... K18: =IF('Data Sheet'!K30>0, 'Data Sheet'!K31/'Data Sheet'!K30, 0) -> 0.21319976
A19: OPM | B19: =IF(B6>0,B6/B4,0) -> 0.19839609 | C19: =IF(C6>0,C6/C4,0) -> 0.18655364 | D19: =IF(D6>0,D6/D4,0) -> 0.21525374 | E19: =IF(E6>0,E6/E4,0) -> 0.23355929 | F19: =IF(F6>0,F6/F4,0) -> 0.2116269 | G19: =IF(G6>0,G6/G4,0) -> 0.16421301 | H19: =IF(H6>0,H6/H4,0) -> 0.14022662 | I19: =IF(I6>0,I6/I4,0) -> 0.17470256 | ... L19: =IF(L6>0,L6/L4,0) -> 0.20056868
G22: TRENDS: | H22: 10 YEARS | I22: 7 YEARS | J22: 5 YEARS | K22: 3 YEARS | L22: RECENT | M22: BEST | N22: WORST
G23: Sales Growth | H23: =IF(B4=0,"",POWER($K4/B4,1/9)-1) -> 0.094983945 | I23: =IF(D4=0,"",POWER($K4/D4,1/7)-1) -> 0.11099602 | J23: =IF(F4=0,"",POWER($K4/F4,1/5)-1) -> 0.13804219 | K23: =IF(H4=0,"",POWER($K4/H4, 1/3)-1) -> 0.042445731 | L23: =IF(ISERROR(MAX(IF(J4=0,"",(K4-J4)/J4),IF(K4=0,"",(L4-K4)/K4))),"",MAX(IF(J4=0,"",(K4-J4)/J4),IF(K4=0,"",(L4-K4)/K4))) -> 0 | M23: =MAX(K23:L23) -> 0.042445731 | N23: =MIN(H23:L23) -> 0
G24: OPM | H24: =IF(SUM(B4:$K$4)=0,"",SUMPRODUCT(B19:$K$19,B4:$K$4)/SUM(B4:$K$4)) -> 0.18819501 | I24: =IF(SUM(E4:$K$4)=0,"",SUMPRODUCT(E19:$K$19,E4:$K$4)/SUM(E4:$K$4)) -> 0.18519916 | J24: =IF(SUM(G4:$K$4)=0,"",SUMPRODUCT(G19:$K$19,G4:$K$4)/SUM(G4:$K$4)) -> 0.17728594 | K24: =IF(SUM(I4:$K$4)=0, "", SUMPRODUCT(I19:$K$19,I4:$K$4)/SUM(I4:$K$4)) -> 0.19102744 | L24: =L19 -> 0.20056868 | M24: =MAX(K24:L24) -> 0.20056868 | N24: =MIN(H24:L24) -> 0.17728594
G25: Price to Earning | H25: =IF(ISERROR(AVERAGEIF(B14:$L14,">0")),"",AVERAGEIF(B14:$L14,">0")) -> 25.045345 | I25: =IF(ISERROR(AVERAGEIF(E14:$L14,">0")),"",AVERAGEIF(E14:$L14,">0")) -> 28.862075 | J25: =IF(ISERROR(AVERAGEIF(G14:$L14,">0")),"",AVERAGEIF(G14:$L14,">0")) -> 32.149879 | K25: =IF(ISERROR(AVERAGEIF(I14:$L14,">0")),"",AVERAGEIF(I14:$L14,">0")) -> 32.722658 | L25: =L14 -> 34.309573 | M25: =MAX(K25:L25) -> 34.309573 | N25: =MIN(H25:L25) -> 25.045345

Sheet Quarters
A1: ='Profit & Loss'!A1 -> TATA POWER COMPANY LTD | E1: =UPDATE | J1: SCREENER.IN
A3: Narration | B3: ='Data Sheet'!B41 -> 45291 | C3: ='Data Sheet'!C41 -> 45382 | D3: ='Data Sheet'!D41 -> 45473 | E3: ='Data Sheet'!E41 -> 45565 | F3: ='Data Sheet'!F41 -> 45657 | G3: ='Data Sheet'!G41 -> 45747 | H3: ='Data Sheet'!H41 -> 45838 | I3: ='Data Sheet'!I41 -> 45930 | ... K3: ='Data Sheet'!K41 -> 46112
A4: Sales | B4: ='Data Sheet'!B42 -> 14651 | C4: ='Data Sheet'!C42 -> 15846.58 | D4: ='Data Sheet'!D42 -> 17293.62 | E4: ='Data Sheet'!E42 -> 15697.67 | F4: ='Data Sheet'!F42 -> 15391.06 | G4: ='Data Sheet'!G42 -> 17095.88 | H4: ='Data Sheet'!H42 -> 18035.07 | I4: ='Data Sheet'!I42 -> 15544.91 | ... K4: ='Data Sheet'!K42 -> 14900.2
A5: Expenses | B5: ='Data Sheet'!B43 -> 12233.58 | C5: ='Data Sheet'!C43 -> 13539.69 | D5: ='Data Sheet'!D43 -> 14231.87 | E5: ='Data Sheet'!E43 -> 12426.76 | F5: ='Data Sheet'!F43 -> 12312.03 | G5: ='Data Sheet'!G43 -> 13850.28 | H5: ='Data Sheet'!H43 -> 14469.9 | I5: ='Data Sheet'!I43 -> 12242.96 | ... K5: ='Data Sheet'!K43 -> 12301.01
A6: Operating Profit | B6: ='Data Sheet'!B50 -> 2417.42 | C6: ='Data Sheet'!C50 -> 2306.89 | D6: ='Data Sheet'!D50 -> 3061.75 | E6: ='Data Sheet'!E50 -> 3270.91 | F6: ='Data Sheet'!F50 -> 3079.03 | G6: ='Data Sheet'!G50 -> 3245.6 | H6: ='Data Sheet'!H50 -> 3565.17 | I6: ='Data Sheet'!I50 -> 3301.95 | ... K6: ='Data Sheet'!K50 -> 2599.19
A7: Other Income | B7: ='Data Sheet'!B44 -> 1091.87 | C7: ='Data Sheet'!C44 -> 1406.63 | D7: ='Data Sheet'!D44 -> 577.72 | E7: ='Data Sheet'!E44 -> 631.75 | F7: ='Data Sheet'!F44 -> 588.55 | G7: ='Data Sheet'!G44 -> 683.58 | H7: ='Data Sheet'!H44 -> 494.42 | I7: ='Data Sheet'!I44 -> 858.65 | ... K7: ='Data Sheet'!K44 -> 1773.3
A8: Depreciation | B8: ='Data Sheet'!B45 -> 926.27 | C8: ='Data Sheet'!C45 -> 1040.77 | D8: ='Data Sheet'!D45 -> 972.89 | E8: ='Data Sheet'!E45 -> 986.69 | F8: ='Data Sheet'!F45 -> 1040.99 | G8: ='Data Sheet'!G45 -> 1116.28 | H8: ='Data Sheet'!H45 -> 1160.91 | I8: ='Data Sheet'!I45 -> 1162.05 | ... K8: ='Data Sheet'!K45 -> 1280.23
A9: Interest | B9: ='Data Sheet'!B46 -> 1094.26 | C9: ='Data Sheet'!C46 -> 1135.72 | D9: ='Data Sheet'!D46 -> 1176.24 | E9: ='Data Sheet'!E46 -> 1143.1 | F9: ='Data Sheet'!F46 -> 1169.9 | G9: ='Data Sheet'!G46 -> 1213.21 | H9: ='Data Sheet'!H46 -> 1279.22 | I9: ='Data Sheet'!I46 -> 1318.65 | ... K9: ='Data Sheet'!K46 -> 1295.26
A10: Profit before tax | B10: ='Data Sheet'!B47 -> 1488.76 | C10: ='Data Sheet'!C47 -> 1537.03 | D10: ='Data Sheet'!D47 -> 1490.34 | E10: ='Data Sheet'!E47 -> 1772.87 | F10: ='Data Sheet'!F47 -> 1456.69 | G10: ='Data Sheet'!G47 -> 1599.69 | H10: ='Data Sheet'!H47 -> 1619.46 | I10: ='Data Sheet'!I47 -> 1679.9 | ... K10: ='Data Sheet'!K47 -> 1797
A11: Tax | B11: ='Data Sheet'!B48 -> 412.64 | C11: ='Data Sheet'!C48 -> 491.44 | D11: ='Data Sheet'!D48 -> 301.71 | E11: ='Data Sheet'!E48 -> 679.79 | F11: ='Data Sheet'!F48 -> 269.15 | G11: ='Data Sheet'!G48 -> 293.6 | H11: ='Data Sheet'!H48 -> 357.14 | I11: ='Data Sheet'!I48 -> 434.51 | ... K11: ='Data Sheet'!K48 -> 381.48
A12: Net profit | B12: ='Data Sheet'!B49 -> 953.01 | C12: ='Data Sheet'!C49 -> 895.21 | D12: ='Data Sheet'!D49 -> 970.91 | E12: ='Data Sheet'!E49 -> 926.53 | F12: ='Data Sheet'!F49 -> 1030.7 | G12: ='Data Sheet'!G49 -> 1042.83 | H12: ='Data Sheet'!H49 -> 1059.86 | I12: ='Data Sheet'!I49 -> 919.44 | ... K12: ='Data Sheet'!K49 -> 995.91
A14: OPM | B14: =IF(B4>0,B6/B4,"") -> 0.16500034 | C14: =IF(C4>0,C6/C4,"") -> 0.14557652 | D14: =IF(D4>0,D6/D4,"") -> 0.17704506 | E14: =IF(E4>0,E6/E4,"") -> 0.20836914 | F14: =IF(F4>0,F6/F4,"") -> 0.20005315 | G14: =IF(G4>0,G6/G4,"") -> 0.18984691 | H14: =IF(H4>0,H6/H4,"") -> 0.19767985 | I14: =IF(I4>0,I6/I4,"") -> 0.21241358 | ... K14: =IF(K4>0,K6/K4,"") -> 0.17443994

Sheet Balance Sheet
A1: ='Profit & Loss'!A1 -> TATA POWER COMPANY LTD | E1: =UPDATE | J1: SCREENER.IN
A3: Narration | B3: ='Data Sheet'!B56 -> 42825 | C3: ='Data Sheet'!C56 -> 43190 | D3: ='Data Sheet'!D56 -> 43555 | E3: ='Data Sheet'!E56 -> 43921 | F3: ='Data Sheet'!F56 -> 44286 | G3: ='Data Sheet'!G56 -> 44651 | H3: ='Data Sheet'!H56 -> 45016 | I3: ='Data Sheet'!I56 -> 45382 | ... K3: ='Data Sheet'!K56 -> 46112
A4: Equity Share Capital | B4: ='Data Sheet'!B57 -> 270.5 | C4: ='Data Sheet'!C57 -> 270.5 | D4: ='Data Sheet'!D57 -> 270.5 | E4: ='Data Sheet'!E57 -> 270.5 | F4: ='Data Sheet'!F57 -> 319.56 | G4: ='Data Sheet'!G57 -> 319.56 | H4: ='Data Sheet'!H57 -> 319.56 | I4: ='Data Sheet'!I57 -> 319.56 | ... K4: ='Data Sheet'!K57 -> 319.56
A5: Reserves | B5: ='Data Sheet'!B58 -> 12944.05 | C5: ='Data Sheet'!C58 -> 16129.38 | D5: ='Data Sheet'!D58 -> 18035.01 | E5: ='Data Sheet'!E58 -> 19295.52 | F5: ='Data Sheet'!F58 -> 22002.7 | G5: ='Data Sheet'!G58 -> 22122 | H5: ='Data Sheet'!H58 -> 28467.87 | I5: ='Data Sheet'!I58 -> 32035.73 | ... K5: ='Data Sheet'!K58 -> 39147.65
A6: Borrowings | B6: ='Data Sheet'!B59 -> 48815.41 | C6: ='Data Sheet'!C59 -> 48589.24 | D6: ='Data Sheet'!D59 -> 48506.04 | E6: ='Data Sheet'!E59 -> 51936.15 | F6: ='Data Sheet'!F59 -> 46707.95 | G6: ='Data Sheet'!G59 -> 51195.12 | H6: ='Data Sheet'!H59 -> 52923 | I6: ='Data Sheet'!I59 -> 53689.45 | ... K6: ='Data Sheet'!K59 -> 76141.27
A7: Other Liabilities | B7: ='Data Sheet'!B60 -> 20799.3 | C7: ='Data Sheet'!C60 -> 16902.68 | D7: ='Data Sheet'!D60 -> 17261.89 | E7: ='Data Sheet'!E60 -> 18171.74 | F7: ='Data Sheet'!F60 -> 29624.63 | G7: ='Data Sheet'!G60 -> 38913.31 | H7: ='Data Sheet'!H60 -> 46385.71 | I7: ='Data Sheet'!I60 -> 53009.66 | ... K7: ='Data Sheet'!K60 -> 58955.76
A8: Total | B8: ='Data Sheet'!B61 -> 82829.26 | C8: ='Data Sheet'!C61 -> 81891.8 | D8: ='Data Sheet'!D61 -> 84073.44 | E8: ='Data Sheet'!E61 -> 89673.91 | F8: ='Data Sheet'!F61 -> 98654.84 | G8: ='Data Sheet'!G61 -> 112549.99 | H8: ='Data Sheet'!H61 -> 128096.14 | I8: ='Data Sheet'!I61 -> 139054.4 | ... K8: ='Data Sheet'!K61 -> 174564.24
A10: Net Block | B10: ='Data Sheet'!B62 -> 46594.79 | C10: ='Data Sheet'!C62 -> 44656.26 | D10: ='Data Sheet'!D62 -> 44304.89 | E10: ='Data Sheet'!E62 -> 47666.36 | F10: ='Data Sheet'!F62 -> 52179.15 | G10: ='Data Sheet'!G62 -> 57389.44 | H10: ='Data Sheet'!H62 -> 61746.66 | I10: ='Data Sheet'!I62 -> 67209.56 | ... K10: ='Data Sheet'!K62 -> 87292.69
A11: Capital Work in Progress | B11: ='Data Sheet'!B63 -> 2177.92 | C11: ='Data Sheet'!C63 -> 1652.6 | D11: ='Data Sheet'!D63 -> 2575.7 | E11: ='Data Sheet'!E63 -> 1611.52 | F11: ='Data Sheet'!F63 -> 3270.26 | G11: ='Data Sheet'!G63 -> 4635.1 | H11: ='Data Sheet'!H63 -> 5376.36 | I11: ='Data Sheet'!I63 -> 11561.31 | ... K11: ='Data Sheet'!K63 -> 14595.13
A12: Investments | B12: ='Data Sheet'!B64 -> 11873.01 | C12: ='Data Sheet'!C64 -> 12428.93 | D12: ='Data Sheet'!D64 -> 13541.87 | E12: ='Data Sheet'!E64 -> 14534.84 | F12: ='Data Sheet'!F64 -> 13149.05 | G12: ='Data Sheet'!G64 -> 14160.33 | H12: ='Data Sheet'!H64 -> 16669.69 | I12: ='Data Sheet'!I64 -> 16315.99 | ... K12: ='Data Sheet'!K64 -> 16574.54
A13: Other Assets | B13: ='Data Sheet'!B65 -> 22183.54 | C13: ='Data Sheet'!C65 -> 23154.01 | D13: ='Data Sheet'!D65 -> 23650.98 | E13: ='Data Sheet'!E65 -> 25861.19 | F13: ='Data Sheet'!F65 -> 30056.38 | G13: ='Data Sheet'!G65 -> 36365.12 | H13: ='Data Sheet'!H65 -> 44303.43 | I13: ='Data Sheet'!I65 -> 43967.54 | ... K13: ='Data Sheet'!K65 -> 56101.88
A14: Total | B14: ='Data Sheet'!B66 -> 82829.26 | C14: ='Data Sheet'!C66 -> 81891.8 | D14: ='Data Sheet'!D66 -> 84073.44 | E14: ='Data Sheet'!E66 -> 89673.91 | F14: ='Data Sheet'!F66 -> 98654.84 | G14: ='Data Sheet'!G66 -> 112549.99 | H14: ='Data Sheet'!H66 -> 128096.14 | I14: ='Data Sheet'!I66 -> 139054.4 | ... K14: ='Data Sheet'!K66 -> 174564.24
A16: Working Capital | B16: =B13-B7 -> 1384.24 | C16: =C13-C7 -> 6251.33 | D16: =D13-D7 -> 6389.09 | E16: =E13-E7 -> 7689.45 | F16: =F13-F7 -> 431.75 | G16: =G13-G7 -> -2548.19 | H16: =H13-H7 -> -2082.28 | I16: =I13-I7 -> -9042.12 | ... K16: =K13-K7 -> -2853.88
A17: Debtors | B17: ='Data Sheet'!B67 -> 3832.12 | C17: ='Data Sheet'!C67 -> 2788.93 | D17: ='Data Sheet'!D67 -> 4445.26 | E17: ='Data Sheet'!E67 -> 4425.9 | F17: ='Data Sheet'!F67 -> 5200.08 | G17: ='Data Sheet'!G67 -> 5979.74 | H17: ='Data Sheet'!H67 -> 6952.15 | I17: ='Data Sheet'!I67 -> 7401.69 | ... K17: ='Data Sheet'!K67 -> 4423.96
A18: Inventory | B18: ='Data Sheet'!B68 -> 1599.56 | C18: ='Data Sheet'!C68 -> 1623.08 | D18: ='Data Sheet'!D68 -> 1706.42 | E18: ='Data Sheet'!E68 -> 1752.35 | F18: ='Data Sheet'!F68 -> 1885.62 | G18: ='Data Sheet'!G68 -> 4231.52 | H18: ='Data Sheet'!H68 -> 3942.88 | I18: ='Data Sheet'!I68 -> 4419.63 | ... K18: ='Data Sheet'!K68 -> 5107.64
A20: Debtor Days | B20: =IF('Profit & Loss'!B4>0,'Balance Sheet'!B17/('Profit & Loss'!B4/365),0) -> 50.701196 | C20: =IF('Profit & Loss'!C4>0,'Balance Sheet'!C17/('Profit & Loss'!C4/365),0) -> 37.926573 | D20: =IF('Profit & Loss'!D4>0,'Balance Sheet'!D17/('Profit & Loss'!D4/365),0) -> 54.299275 | E20: =IF('Profit & Loss'!E4>0,'Balance Sheet'!E17/('Profit & Loss'!E4/365),0) -> 55.44457 | F20: =IF('Profit & Loss'!F4>0,'Balance Sheet'!F17/('Profit & Loss'!F4/365),0) -> 58.037832 | G20: =IF('Profit & Loss'!G4>0,'Balance Sheet'!G17/('Profit & Loss'!G4/365),0) -> 50.976783 | H20: =IF('Profit & Loss'!H4>0,'Balance Sheet'!H17/('Profit & Loss'!H4/365),0) -> 46.045674 | I20: =IF('Profit & Loss'!I4>0,'Balance Sheet'!I17/('Profit & Loss'!I4/365),0) -> 43.96526 | ... K20: =IF('Profit & Loss'!K4>0,'Balance Sheet'!K17/('Profit & Loss'!K4/365),0) -> 25.865479
A21: Inventory Turnover | B21: =IF('Balance Sheet'!B18>0,'Profit & Loss'!B4/'Balance Sheet'!B18,0) -> 17.246987 | C21: =IF('Balance Sheet'!C18>0,'Profit & Loss'!C4/'Balance Sheet'!C18,0) -> 16.536628 | D21: =IF('Balance Sheet'!D18>0,'Profit & Loss'!D4/'Balance Sheet'!D18,0) -> 17.510964 | E21: =IF('Balance Sheet'!E18>0,'Profit & Loss'!E4/'Balance Sheet'!E18,0) -> 16.627027 | F21: =IF('Balance Sheet'!F18>0,'Profit & Loss'!F4/'Balance Sheet'!F18,0) -> 17.343532 | G21: =IF('Balance Sheet'!G18>0,'Profit & Loss'!G4/'Balance Sheet'!G18,0) -> 10.118272 | H21: =IF('Balance Sheet'!H18>0,'Profit & Loss'!H4/'Balance Sheet'!H18,0) -> 13.97686 | I21: =IF('Balance Sheet'!I18>0,'Profit & Loss'!I4/'Balance Sheet'!I18,0) -> 13.90363 | ... K21: =IF('Balance Sheet'!K18>0,'Profit & Loss'!K4/'Balance Sheet'!K18,0) -> 12.22259
A23: Return on Equity | B23: =IF(SUM('Balance Sheet'!B4:B5)>0,'Profit & Loss'!B12/SUM('Balance Sheet'!B4:B5),"") -> 0.06784567 | C23: =IF(SUM('Balance Sheet'!C4:C5)>0,'Profit & Loss'!C12/SUM('Balance Sheet'!C4:C5),"") -> 0.14684864 | D23: =IF(SUM('Balance Sheet'!D4:D5)>0,'Profit & Loss'!D12/SUM('Balance Sheet'!D4:D5),"") -> 0.1287148 | E23: =IF(SUM('Balance Sheet'!E4:E5)>0,'Profit & Loss'!E12/SUM('Balance Sheet'!E4:E5),"") -> 0.051997289 | F23: =IF(SUM('Balance Sheet'!F4:F5)>0,'Profit & Loss'!F12/SUM('Balance Sheet'!F4:F5),"") -> 0.050504743 | G23: =IF(SUM('Balance Sheet'!G4:G5)>0,'Profit & Loss'!G12/SUM('Balance Sheet'!G4:G5),"") -> 0.077599775 | H23: =IF(SUM('Balance Sheet'!H4:H5)>0,'Profit & Loss'!H12/SUM('Balance Sheet'!H4:H5),"") -> 0.1158992 | I23: =IF(SUM('Balance Sheet'!I4:I5)>0,'Profit & Loss'!I12/SUM('Balance Sheet'!I4:I5),"") -> 0.11423943 | ... K23: =IF(SUM('Balance Sheet'!K4:K5)>0,'Profit & Loss'!K12/SUM('Balance Sheet'!K4:K5),"") -> 0.094944385
A24: Return on Capital Emp | C24: =IF((B4+B5+B6+C4+C5+C6)>0,('Profit & Loss'!C10+'Profit & Loss'!C9)*2/(B4+B5+B6+C4+C5+C6),"") -> 0.1028869 | D24: =IF((C4+C5+C6+D4+D5+D6)>0,('Profit & Loss'!D10+'Profit & Loss'!D9)*2/(C4+C5+C6+D4+D5+D6),"") -> 0.11932033 | E24: =IF((D4+D5+D6+E4+E5+E6)>0,('Profit & Loss'!E10+'Profit & Loss'!E9)*2/(D4+D5+D6+E4+E5+E6),"") -> 0.093290239 | F24: =IF((E4+E5+E6+F4+F5+F6)>0,('Profit & Loss'!F10+'Profit & Loss'!F9)*2/(E4+E5+E6+F4+F5+F6),"") -> 0.084691087 | G24: =IF((F4+F5+F6+G4+G5+G6)>0,('Profit & Loss'!G10+'Profit & Loss'!G9)*2/(F4+F5+F6+G4+G5+G6),"") -> 0.089638037 | H24: =IF((G4+G5+G6+H4+H5+H6)>0,('Profit & Loss'!H10+'Profit & Loss'!H9)*2/(G4+G5+G6+H4+H5+H6),"") -> 0.12653792 | I24: =IF((H4+H5+H6+I4+I5+I6)>0,('Profit & Loss'!I10+'Profit & Loss'!I9)*2/(H4+H5+H6+I4+I5+I6),"") -> 0.1235758 | J24: =IF((I4+I5+I6+J4+J5+J6)>0,('Profit & Loss'!J10+'Profit & Loss'!J9)*2/(I4+I5+I6+J4+J5+J6),"") -> 0.11931787 | K24: =IF((J4+J5+J6+K4+K5+K6)>0,('Profit & Loss'!K10+'Profit & Loss'!K9)*2/(J4+J5+J6+K4+K5+K6),"") -> 0.11098414

Sheet Cash Flow
A1: ='Balance Sheet'!A1 -> TATA POWER COMPANY LTD | E1: =UPDATE | J1: SCREENER.IN
A3: Narration | B3: ='Data Sheet'!B81 -> 42825 | C3: ='Data Sheet'!C81 -> 43190 | D3: ='Data Sheet'!D81 -> 43555 | E3: ='Data Sheet'!E81 -> 43921 | F3: ='Data Sheet'!F81 -> 44286 | G3: ='Data Sheet'!G81 -> 44651 | H3: ='Data Sheet'!H81 -> 45016 | I3: ='Data Sheet'!I81 -> 45382 | ... K3: ='Data Sheet'!K81 -> 46112
A4: Cash from Operating Activity | B4: ='Data Sheet'!B82 -> 7014.18 | C4: ='Data Sheet'!C82 -> 6363.85 | D4: ='Data Sheet'!D82 -> 4573.79 | E4: ='Data Sheet'!E82 -> 7375.32 | F4: ='Data Sheet'!F82 -> 8345.12 | G4: ='Data Sheet'!G82 -> 6692.73 | H4: ='Data Sheet'!H82 -> 7165.59 | I4: ='Data Sheet'!I82 -> 12504.37 | ... K4: ='Data Sheet'!K82 -> 5993.33
A5: Cash from Investing Activity | B5: ='Data Sheet'!B83 -> -7372.73 | C5: ='Data Sheet'!C83 -> -1511.65 | D5: ='Data Sheet'!D83 -> -272.34 | E5: ='Data Sheet'!E83 -> -492.88 | F5: ='Data Sheet'!F83 -> 993.33 | G5: ='Data Sheet'!G83 -> -6250.47 | H5: ='Data Sheet'!H83 -> -7263.1 | I5: ='Data Sheet'!I83 -> -8935.37 | ... K5: ='Data Sheet'!K83 -> -14128.65
A6: Cash from Financing Activity | B6: ='Data Sheet'!B84 -> 937.34 | C6: ='Data Sheet'!C84 -> -4726.26 | D6: ='Data Sheet'!D84 -> -5184.45 | E6: ='Data Sheet'!E84 -> -5109.57 | F6: ='Data Sheet'!F84 -> -7602.88 | G6: ='Data Sheet'!G84 -> -1183.2 | H6: ='Data Sheet'!H84 -> 1340.77 | I6: ='Data Sheet'!I84 -> -4497.43 | ... K6: ='Data Sheet'!K84 -> 7782.63
A7: Net Cash Flow | B7: ='Data Sheet'!B85 -> 578.79 | C7: ='Data Sheet'!C85 -> 125.94 | D7: ='Data Sheet'!D85 -> -883 | E7: ='Data Sheet'!E85 -> 1772.87 | F7: ='Data Sheet'!F85 -> 1735.57 | G7: ='Data Sheet'!G85 -> -740.94 | H7: ='Data Sheet'!H85 -> 1243.26 | I7: ='Data Sheet'!I85 -> -928.43 | ... K7: ='Data Sheet'!K85 -> -352.69

Sheet Customization
A1: How to use it?
A3: You can customize this workbook as you want.
B4: You can add custom formating, add conditional formating, add your own formulas… do ANYTHING.
B5: Please don't edit the "Data Sheet" only.
A7: After customization, you can upload this back on Screener.
B8: Upload on: | C8: https://www.screener.in/excel/
A10: Download your customized workbooks now onwards.
B11: Now whenever you will "Export to excel" from Screener, it will export your customized file.
A14: TESTING:
B15: This is a testing feature currently.
B16: You can report any formula errors on the worksheet at: support@screener.in

Sheet Data Sheet
A1: COMPANY NAME | B1: TATA POWER COMPANY LTD | E1: =IF(B2<>B3, "A NEW VERSION OF THE WORKSHEET IS AVAILABLE", "")
A2: LATEST VERSION | B2: 2.1 | E2: PLEASE DO NOT MAKE ANY CHANGES TO THIS SHEET
A3: CURRENT VERSION | B3: 2.1
A5: META
A6: Number of shares | B6: =IF(B9>0, B9/B8, 0) -> 319.53396
A7: Face Value | B7: 1
A8: Current Price | B8: 402.35
A9: Market Capitalization | B9: 128564.49
A15: PROFIT & LOSS
A16: Report Date | B16: 42825 | C16: 43190 | D16: 43555 | E16: 43921 | F16: 44286 | G16: 44651 | H16: 45016 | I16: 45382 | J16: 45747 | K16: 46112
A17: Sales | B17: 27587.59 | C17: 26840.27 | D17: 29881.06 | E17: 29136.37 | F17: 32703.31 | G17: 42815.67 | H17: 55109.08 | I17: 61448.9 | J17: 65478.24 | K17: 62428.59
A18: Raw Material Cost
A19: Change in Inventory | B19: -28.34 | C19: 8.51 | D19: -24.37 | E19: 15.64 | F19: -0.41 | G19: 199.22 | H19: -43.53 | I19: 51.78 | J19: 440.76 | K19: 84.11
A20: Power and Fuel | B20: 17921.05 | C20: 16356.15 | D20: 18918.9 | E20: 17100.03 | F20: 20037.56 | G20: 26764.37 | H20: 36708.56 | I20: 39584.79 | J20: 39363.54 | K20: 35764.04
A21: Other Mfr. Exp | B21: 1720.75 | C21: 2041.68 | D21: 2056.1 | E21: 2013.68 | F21: 2533.43 | G21: 3942.93 | H21: 5007.21 | I21: 5272.77 | J21: 6306.19 | K21: 6743.03
A22: Employee Cost | B22: 1342.92 | C22: 1475 | D22: 1497.6 | E22: 1541.05 | F22: 2414.24 | G22: 3731.29 | H22: 3801.4 | I22: 4264.99 | J22: 4649.25 | K22: 5099.95
A23: Selling and admin | B23: 481.89 | C23: 511.78 | D23: 466.39 | E23: 401.51 | F23: 523.94 | G23: 730.58 | H23: 1016.41 | I23: 1017.98 | J23: 1055.18 | K23: 1213.37
A24: Other Expenses | B24: 619.37 | C24: 1457.02 | D24: 485.69 | E24: 1290.67 | F24: 272.83 | G24: 814.83 | H24: 804.21 | I24: 624.87 | J24: 2379.25 | K24: 421.04
A25: Other Income | B25: 1297.37 | C25: 3873.32 | D25: 3824.37 | E25: 2280.15 | F25: 1774.96 | G25: 2485.5 | H25: 5540.09 | I25: 3416.33 | J25: 2973.33 | K25: 3432.6
A26: Depreciation | B26: 1955.59 | C26: 2346.17 | D26: 2393.13 | E26: 2633.56 | F26: 2744.94 | G26: 3122.2 | H26: 3439.2 | I26: 3786.37 | J26: 4116.86 | K26: 4811.09
A27: Interest | B27: 3364.96 | C27: 3761.48 | D27: 4170 | E27: 4493.73 | F27: 4010.39 | G27: 3859.02 | H27: 4371.65 | I27: 4633.22 | J27: 4702.44 | K27: 5256.79
A28: Profit before tax | B28: 1450.09 | C28: 2772.82 | D28: 3693.25 | E28: 1957.93 | F28: 1940.53 | G28: 2535.17 | H28: 5457 | I28: 5732.02 | J28: 6319.62 | K28: 6635.99
A29: Tax | B29: 350.46 | C29: 161.97 | D29: 1087.59 | E29: 641.49 | F29: 501.88 | G29: 379.56 | H29: 1647.33 | I29: 1451.92 | J29: 1544.25 | K29: 1518.43
A30: Net profit | B30: 896.55 | C30: 2408.3 | D30: 2356.19 | E30: 1017.38 | F30: 1127.38 | G30: 1741.46 | H30: 3336.44 | I30: 3696.25 | J30: 3971 | K30: 3747.19
A31: Dividend Amount | B31: 351.65 | C31: 351.65 | D31: 351.65 | E31: 419.28 | F31: 495.32 | G31: 559.23 | H31: 639.12 | I31: 639.12 | J31: 719.01 | K31: 798.9
A40: Quarters
A41: Report Date | B41: 45291 | C41: 45382 | D41: 45473 | E41: 45565 | F41: 45657 | G41: 45747 | H41: 45838 | I41: 45930 | J41: 46022 | K41: 46112
A42: Sales | B42: 14651 | C42: 15846.58 | D42: 17293.62 | E42: 15697.67 | F42: 15391.06 | G42: 17095.88 | H42: 18035.07 | I42: 15544.91 | J42: 13948.41 | K42: 14900.2
A43: Expenses | B43: 12233.58 | C43: 13539.69 | D43: 14231.87 | E43: 12426.76 | F43: 12312.03 | G43: 13850.28 | H43: 14469.9 | I43: 12242.96 | J43: 10893.5 | K43: 12301.01
A44: Other Income | B44: 1091.87 | C44: 1406.63 | D44: 577.72 | E44: 631.75 | F44: 588.55 | G44: 683.58 | H44: 494.42 | I44: 858.65 | J44: 1056.28 | K44: 1773.3
A45: Depreciation | B45: 926.27 | C45: 1040.77 | D45: 972.89 | E45: 986.69 | F45: 1040.99 | G45: 1116.28 | H45: 1160.91 | I45: 1162.05 | J45: 1207.9 | K45: 1280.23
A46: Interest | B46: 1094.26 | C46: 1135.72 | D46: 1176.24 | E46: 1143.1 | F46: 1169.9 | G46: 1213.21 | H46: 1279.22 | I46: 1318.65 | J46: 1363.66 | K46: 1295.26
A47: Profit before tax | B47: 1488.76 | C47: 1537.03 | D47: 1490.34 | E47: 1772.87 | F47: 1456.69 | G47: 1599.69 | H47: 1619.46 | I47: 1679.9 | J47: 1539.63 | K47: 1797
A48: Tax | B48: 412.64 | C48: 491.44 | D48: 301.71 | E48: 679.79 | F48: 269.15 | G48: 293.6 | H48: 357.14 | I48: 434.51 | J48: 345.3 | K48: 381.48
A49: Net profit | B49: 953.01 | C49: 895.21 | D49: 970.91 | E49: 926.53 | F49: 1030.7 | G49: 1042.83 | H49: 1059.86 | I49: 919.44 | J49: 771.98 | K49: 995.91
A50: Operating Profit | B50: 2417.42 | C50: 2306.89 | D50: 3061.75 | E50: 3270.91 | F50: 3079.03 | G50: 3245.6 | H50: 3565.17 | I50: 3301.95 | J50: 3054.91 | K50: 2599.19
A55: BALANCE SHEET
A56: Report Date | B56: 42825 | C56: 43190 | D56: 43555 | E56: 43921 | F56: 44286 | G56: 44651 | H56: 45016 | I56: 45382 | J56: 45747 | K56: 46112
A57: Equity Share Capital | B57: 270.5 | C57: 270.5 | D57: 270.5 | E57: 270.5 | F57: 319.56 | G57: 319.56 | H57: 319.56 | I57: 319.56 | J57: 319.56 | K57: 319.56
A58: Reserves | B58: 12944.05 | C58: 16129.38 | D58: 18035.01 | E58: 19295.52 | F58: 22002.7 | G58: 22122 | H58: 28467.87 | I58: 32035.73 | J58: 35521.11 | K58: 39147.65
...

Sheet Peer Company Database
B2: COMPANY_NAME | C2: BSE | D2: NSE | E2: Industry
B3: 20 MICRONS LTD | C3: 533022 | D3: 20MICRONS | E3: Mining
B4: 21ST CENTURY MANAGEMENT SERVICES LTD | C4: 526921 | D4: 21STCENMGM | E4: Other Financial Services
B5: 3I INFOTECH LTD | C5: 532628 | D5: 3IINFOTECH | E5: IT Consulting & Software
B6: 3M (INDIA) LTD | C6: 523395 | D6: 3M(INDIA) | E6: Diversified
B7: 3M INDIA LTD | C7: 523395 | D7: 3MINDIA | E7: Diversified
B8: 3P LAND HOLDINGS LTD | C8: 516092 | D8: 3PLAND | E8: Paper & Paper Products
B9: 5PAISA CAPITAL LTD | C9: 540776 | D9: 5PAISA | E9: Other Financial Services
B10: 63 MOONS TECHNOLOGIES LTD | C10: 526881 | D10: 63MOONS | E10: IT Consulting & Software
B11: 7NR RETAIL LTD | C11: 540615 | D11: Not Listed | E11: Specialty Retail
B12: 7SEAS ENTERTAINMENT LTD | C12: 540874 | D12: Not Listed | E12: Movies & Entertainment
B13: 8K MILES SOFTWARE SERVICES LTD | C13: 512161 | D13: 8KMILES | E13: Internet Software & Services
B14: A & M FEBCON LTD | C14: 540697 | D14: Not Listed | E14: Industrial Machinery
B15: A AND M JUMBO BAGS LTD | C15: Not Listed | D15: AMJUMBO | E15: SME
B16: A INFRASTRUCTURE LTD | C16: 539620 | D16: Not Listed | E16: Cement & Cement Products
B17: A K SPINTEX LTD | C17: 539300 | D17: Not Listed | E17: Textiles
B18: A K CAPITAL SERVICES LTD | C18: 530499 | D18: Not Listed | E18: Finance (including NBFCs)
B19: A.F. Enterprises Ltd | C19: 538351 | D19: AFEL | E19: Investment Companies
B20: A-1 ACID LTD | C20: 542012 | D20: Not Listed | E20: Comm.Trading & Distribution
B21: A2Z INFRA ENGINEERING LTD | C21: 533292 | D21: A2ZINFRA | E21: Utilities:Non-Elec.
B22: AADHAAR VENTURES (INDIA) LTD | C22: 531611 | D22: Not Listed | E22: Finance (including NBFCs)
B23: AADHAAR VENTURES INDIA LTD | C23: 531611 | D23: Not Listed | E23: Finance (including NBFCs)
B24: AAKASH EXPLORATION SERVICES LTD | C24: Not Listed | D24: AAKASH | E24: SME
B25: AANANDA LAKSHMI SPINNING MILLS LTD | C25: 539096 | D25: Not Listed | E25: Textiles
B26: AANCHAL ISPAT LTD | C26: 538812 | D26: Not Listed | E26: Iron & Steel/Interm.Products
B27: AAR COMMERCIAL COMPANY LTD | C27: 539632 | D27: Not Listed | E27: Distributors
B28: Aar Shyam India Investment Company Ltd | C28: 542377 | D28: AARSHYAM | E28: Finance (including NBFCs)
B29: AAREY DRUGS & PHARMACEUTICALS LTD | C29: 524412 | D29: Not Listed | E29: Pharmaceuticals
B30: AARON INDUSTRIES LTD | C30: Not Listed | D30: AARON | E30: SME
B31: Aartech Solonics Ltd | C31: 542580 | D31: AARTECH | E31: Heavy Electrical Equipment
B32: AARTI DRUGS LTD | C32: 524348 | D32: AARTIDRUGS | E32: Pharmaceuticals
B33: AARTI INDUSTRIES LTD | C33: 524208 | D33: AARTIIND | E33: Commodity Chemicals
B34: AARV INFRATEL LTD | C34: 526488 | D34: Not Listed | E34: Textiles
B35: AARVEE DENIMS & EXPORTS LTD | C35: 514274 | D35: AARVEEDEN | E35: Textiles
B36: AARVI ENCON LTD | C36: Not Listed | D36: AARVI | E36: SME
B37: AASHEE INFOTECH LTD | C37: 519319 | D37: Not Listed | E37: Internet Software & Services
B38: AASWA TRADING & EXPORTS LTD | C38: 512038 | D38: Not Listed | E38: Comm.Trading & Distribution
B39: AAVAS FINANCIERS LTD | C39: 541988 | D39: AAVAS | E39: Housing Finance
B40: AAYUSH FOOD AND HERBS LTD | C40: 539528 | D40: Not Listed | E40: Packaged Foods
B41: ABAN OFFSHORE LTD | C41: 523204 | D41: ABAN | E41: Exploration & Production
...

Sheet Financials ->

Sheet Historical Financial Statements
B2: ="Historical Financial Statement - "&'Data Sheet'!B1 -> Historical Financial Statement - TATA POWER COMPANY LTD | M2: Seasonality | N2: FORECAST
B3: Year | C3: ='Data Sheet'!B16 -> 42825 | D3: ='Data Sheet'!C16 -> 43190 | E3: ='Data Sheet'!D16 -> 43555 | F3: ='Data Sheet'!E16 -> 43921 | G3: ='Data Sheet'!F16 -> 44286 | H3: ='Data Sheet'!G16 -> 44651 | I3: ='Data Sheet'!H16 -> 45016 | J3: ='Data Sheet'!I16 -> 45382 | ... L3: ='Data Sheet'!K16 -> 46112 | N3: =L3+365 -> 46477 | O3: =N3+365 -> 46842 | P3: =O3+365 -> 47207 | Q3: =P3+365 -> 47572 | R3: =Q3+365 -> 47937
A5: # | B5: Income Statement
B6: Sales | C6: ='Data Sheet'!B17 -> 27587.59 | D6: ='Data Sheet'!C17 -> 26840.27 | E6: ='Data Sheet'!D17 -> 29881.06 | F6: ='Data Sheet'!E17 -> 29136.37 | G6: ='Data Sheet'!F17 -> 32703.31 | H6: ='Data Sheet'!G17 -> 42815.67 | I6: ='Data Sheet'!H17 -> 55109.08 | J6: ='Data Sheet'!I17 -> 61448.9 | ... L6: ='Data Sheet'!K17 -> 62428.59 | M6: =IFERROR(_xlfn.FORECAST.ETS.SEASONALITY($C6:$L6,$C$3:$L$3),"") -> 0 | N6: =IFERROR(_xlfn.FORECAST.ETS(N$3,$C6:$L6,$C$3:$L$3,$M$6),"") -> 67458.314 | O6: =IFERROR(_xlfn.FORECAST.ETS(O$3,$C6:$L6,$C$3:$L$3,$M$6),"") -> 72474.296 | P6: =IFERROR(_xlfn.FORECAST.ETS(P$3,$C6:$L6,$C$3:$L$3,$M$6),"") -> 77503.982 | Q6: =IFERROR(_xlfn.FORECAST.ETS(Q$3,$C6:$L6,$C$3:$L$3,$M$6),"") -> 82533.706 | R6: =IFERROR(_xlfn.FORECAST.ETS(R$3,$C6:$L6,$C$3:$L$3,$M$6),"") -> 87563.431
B7: Sales Growth | C7: 0 | D7: =D6/C6-1 -> -0.027088992 | E7: =E6/D6-1 -> 0.11329208 | F7: =F6/E6-1 -> -0.024921807 | G7: =G6/F6-1 -> 0.12242225 | H7: =H6/G6-1 -> 0.30921518 | I7: =I6/H6-1 -> 0.28712408 | J7: =J6/I6-1 -> 0.1150413 | K7: =K6/J6-1 -> 0.065572207 | L7: =L6/K6-1 -> -0.046575015 | M7: =IFERROR(_xlfn.FORECAST.ETS.SEASONALITY($C7:$L7,$C$3:$L$3),"") -> 0 | N7: =N6/L6-1 -> 0.080567639 | O7: =O6/N6-1 -> 0.07435676 | P7: =P6/O6-1 -> 0.069399591 | Q7: =Q6/P6-1 -> 0.064896331 | R7: =R6/Q6-1 -> 0.060941455
M8: =IFERROR(_xlfn.FORECAST.ETS.SEASONALITY($C8:$L8,$C$3:$L$3),"") | N8: =IFERROR(_xlfn.FORECAST.ETS(N$3,$C8:$L8,$C$3:$L$3,$M$6),"") | O8: =IFERROR(_xlfn.FORECAST.ETS(O$3,$C8:$L8,$C$3:$L$3,$M$6),"") | P8: =IFERROR(_xlfn.FORECAST.ETS(P$3,$C8:$L8,$C$3:$L$3,$M$6),"") | Q8: =IFERROR(_xlfn.FORECAST.ETS(Q$3,$C8:$L8,$C$3:$L$3,$M$6),"") | R8: =IFERROR(_xlfn.FORECAST.ETS(R$3,$C8:$L8,$C$3:$L$3,$M$6),"")
B9: COGS | C9: =IFERROR(SUM('Data Sheet'!B18,'Data Sheet'!B20:B22)-1*'Data Sheet'!B19,0) -> 21013.06 | D9: =IFERROR(SUM('Data Sheet'!C18,'Data Sheet'!C20:C22)-1*'Data Sheet'!C19,0) -> 19864.32 | E9: =IFERROR(SUM('Data Sheet'!D18,'Data Sheet'!D20:D22)-1*'Data Sheet'!D19,0) -> 22496.97 | F9: =IFERROR(SUM('Data Sheet'!E18,'Data Sheet'!E20:E22)-1*'Data Sheet'!E19,0) -> 20639.12 | G9: =IFERROR(SUM('Data Sheet'!F18,'Data Sheet'!F20:F22)-1*'Data Sheet'!F19,0) -> 24985.64 | H9: =IFERROR(SUM('Data Sheet'!G18,'Data Sheet'!G20:G22)-1*'Data Sheet'!G19,0) -> 34239.37 | I9: =IFERROR(SUM('Data Sheet'!H18,'Data Sheet'!H20:H22)-1*'Data Sheet'!H19,0) -> 45560.7 | J9: =IFERROR(SUM('Data Sheet'!I18,'Data Sheet'!I20:I22)-1*'Data Sheet'!I19,0) -> 49070.77 | ... L9: =IFERROR(SUM('Data Sheet'!K18,'Data Sheet'!K20:K22)-1*'Data Sheet'!K19,0) -> 47522.91
B10: COGS % Sales | C10: =C9/C6 -> 0.76168524 | D10: =D9/D6 -> 0.7400939 | E10: =E9/E6 -> 0.75288393 | F10: =F9/F6 -> 0.70836278 | G10: =G9/G6 -> 0.76400951 | H10: =H9/H6 -> 0.7996925 | I10: =I9/I6 -> 0.82673672 | J10: =J9/J6 -> 0.79856222 | ... L10: =L9/L6 -> 0.76123632
B12: Gross Profit | C12: =C6-C9 -> 6574.53 | D12: =D6-D9 -> 6975.95 | E12: =E6-E9 -> 7384.09 | F12: =F6-F9 -> 8497.25 | G12: =G6-G9 -> 7717.67 | H12: =H6-H9 -> 8576.3 | I12: =I6-I9 -> 9548.38 | J12: =J6-J9 -> 12378.13 | ... L12: =L6-L9 -> 14905.68
B13: Gross Margin | C13: =C12/C6 -> 0.23831476 | D13: =D12/D6 -> 0.2599061 | E13: =E12/E6 -> 0.24711607 | F13: =F12/F6 -> 0.29163722 | G13: =G12/G6 -> 0.23599049 | H13: =H12/H6 -> 0.2003075 | I13: =I12/I6 -> 0.17326328 | J13: =J12/J6 -> 0.20143778 | ... L13: =L12/L6 -> 0.23876368
B15: Selling & General Expenses | C15: =IFERROR('Data Sheet'!B23,0) -> 481.89 | D15: =IFERROR('Data Sheet'!C23,0) -> 511.78 | E15: =IFERROR('Data Sheet'!D23,0) -> 466.39 | F15: =IFERROR('Data Sheet'!E23,0) -> 401.51 | G15: =IFERROR('Data Sheet'!F23,0) -> 523.94 | H15: =IFERROR('Data Sheet'!G23,0) -> 730.58 | I15: =IFERROR('Data Sheet'!H23,0) -> 1016.41 | J15: =IFERROR('Data Sheet'!I23,0) -> 1017.98 | ... L15: =IFERROR('Data Sheet'!K23,0) -> 1213.37
B16: S&G Exp % Sales | C16: =C15/C6 -> 0.017467637 | D16: =D15/D6 -> 0.019067617 | E16: =E15/E6 -> 0.015608215 | F16: =F15/F6 -> 0.013780371 | G16: =G15/G6 -> 0.016021008 | H16: =H15/H6 -> 0.017063379 | I16: =I15/I6 -> 0.018443603 | J16: =J15/J6 -> 0.016566285 | ... L16: =L15/L6 -> 0.019436127
B18: EBITDA | C18: =C12-C15 -> 6092.64 | D18: =D12-D15 -> 6464.17 | E18: =E12-E15 -> 6917.7 | F18: =F12-F15 -> 8095.74 | G18: =G12-G15 -> 7193.73 | H18: =H12-H15 -> 7845.72 | I18: =I12-I15 -> 8531.97 | J18: =J12-J15 -> 11360.15 | ... L18: =L12-L15 -> 13692.31
B19: EBITDA Margin | C19: =C18/C6 -> 0.22084713 | D19: =D18/D6 -> 0.24083849 | E19: =E18/E6 -> 0.23150785 | F19: =F18/F6 -> 0.27785685 | G19: =G18/G6 -> 0.21996948 | H19: =H18/H6 -> 0.18324413 | I19: =I18/I6 -> 0.15481968 | J19: =J18/J6 -> 0.18487149 | ... L19: =L18/L6 -> 0.21932755
B21: Depreciation | C21: ='Data Sheet'!B26 -> 1955.59 | D21: ='Data Sheet'!C26 -> 2346.17 | E21: ='Data Sheet'!D26 -> 2393.13 | F21: ='Data Sheet'!E26 -> 2633.56 | G21: ='Data Sheet'!F26 -> 2744.94 | H21: ='Data Sheet'!G26 -> 3122.2 | I21: ='Data Sheet'!H26 -> 3439.2 | J21: ='Data Sheet'!I26 -> 3786.37 | ... L21: ='Data Sheet'!K26 -> 4811.09
B22: Depreciation % Sales | C22: =C21/C6 -> 0.070886583 | D22: =D21/D6 -> 0.08741231 | E22: =E21/E6 -> 0.080088524 | F22: =F21/F6 -> 0.090387375 | G22: =G21/G6 -> 0.083934623 | H22: =H21/H6 -> 0.0729219 | I22: =I21/I6 -> 0.062407139 | J22: =J21/J6 -> 0.06161819 | ... L22: =L21/L6 -> 0.077065492
B24: EBIT | C24: =C18-C21 -> 4137.05 | D24: =D18-D21 -> 4118 | E24: =E18-E21 -> 4524.57 | F24: =F18-F21 -> 5462.18 | G24: =G18-G21 -> 4448.79 | H24: =H18-H21 -> 4723.52 | I24: =I18-I21 -> 5092.77 | J24: =J18-J21 -> 7573.78 | ... L24: =L18-L21 -> 8881.22
B25: EBIT % Sales | C25: =C24/C6 -> 0.14996054 | D25: =D24/D6 -> 0.15342618 | E25: =E24/E6 -> 0.15141933 | F25: =F24/F6 -> 0.18746948 | G25: =G24/G6 -> 0.13603485 | H25: =H24/H6 -> 0.11032223 | I25: =I24/I6 -> 0.092412539 | J25: =J24/J6 -> 0.1232533 | ... L25: =L24/L6 -> 0.14226206
B27: Other Income/Expences | C27: ='Data Sheet'!B25-'Data Sheet'!B24 -> 678 | D27: ='Data Sheet'!C25-'Data Sheet'!C24 -> 2416.3 | E27: ='Data Sheet'!D25-'Data Sheet'!D24 -> 3338.68 | F27: ='Data Sheet'!E25-'Data Sheet'!E24 -> 989.48 | G27: ='Data Sheet'!F25-'Data Sheet'!F24 -> 1502.13 | H27: ='Data Sheet'!G25-'Data Sheet'!G24 -> 1670.67 | I27: ='Data Sheet'!H25-'Data Sheet'!H24 -> 4735.88 | J27: ='Data Sheet'!I25-'Data Sheet'!I24 -> 2791.46 | ... L27: ='Data Sheet'!K25-'Data Sheet'!K24 -> 3011.56
B28: OI/E % of Sales | C28: =C27/C6 -> 0.024576268 | D28: =D27/D6 -> 0.090025175 | E28: =E27/E6 -> 0.11173231 | F28: =F27/F6 -> 0.033960305 | G28: =G27/G6 -> 0.045932048 | H28: =H27/H6 -> 0.03902006 | I28: =I27/I6 -> 0.085936474 | J28: =J27/J6 -> 0.045427339 | ... L28: =L27/L6 -> 0.048240077
B30: Interest | C30: ='Data Sheet'!B27 -> 3364.96 | D30: ='Data Sheet'!C27 -> 3761.48 | E30: ='Data Sheet'!D27 -> 4170 | F30: ='Data Sheet'!E27 -> 4493.73 | G30: ='Data Sheet'!F27 -> 4010.39 | H30: ='Data Sheet'!G27 -> 3859.02 | I30: ='Data Sheet'!H27 -> 4371.65 | J30: ='Data Sheet'!I27 -> 4633.22 | ... L30: ='Data Sheet'!K27 -> 5256.79
B31: Interest % of Sales | C31: =C30/C6 -> 0.12197368 | D31: =D30/D6 -> 0.14014315 | E31: =E30/E6 -> 0.13955328 | F31: =F30/F6 -> 0.15423095 | G31: =G30/G6 -> 0.12262948 | H31: =H30/H6 -> 0.09013102 | I31: =I30/I6 -> 0.079327218 | J31: =J30/J6 -> 0.07539956 | ... L31: =L30/L6 -> 0.084204849
B33: EBT | C33: =C24+C27-C30 -> 1450.09 | D33: =D24+D27-D30 -> 2772.82 | E33: =E24+E27-E30 -> 3693.25 | F33: =F24+F27-F30 -> 1957.93 | G33: =G24+G27-G30 -> 1940.53 | H33: =H24+H27-H30 -> 2535.17 | I33: =I24+I27-I30 -> 5457 | J33: =J24+J27-J30 -> 5732.02 | ... L33: =L24+L27-L30 -> 6635.99
B34: EBT % of Sales | C34: =C33/C6 -> 0.052563127 | D34: =D33/D6 -> 0.1033082 | E34: =E33/E6 -> 0.12359836 | F34: =F33/F6 -> 0.067198831 | G34: =G33/G6 -> 0.059337419 | H34: =H33/H6 -> 0.059211265 | I34: =I33/I6 -> 0.099021795 | J34: =J33/J6 -> 0.093281084 | ... L34: =L33/L6 -> 0.10629729
B36: Tax | C36: ='Data Sheet'!B29 -> 350.46 | D36: ='Data Sheet'!C29 -> 161.97 | E36: ='Data Sheet'!D29 -> 1087.59 | F36: ='Data Sheet'!E29 -> 641.49 | G36: ='Data Sheet'!F29 -> 501.88 | H36: ='Data Sheet'!G29 -> 379.56 | I36: ='Data Sheet'!H29 -> 1647.33 | J36: ='Data Sheet'!I29 -> 1451.92 | ... L36: ='Data Sheet'!K29 -> 1518.43
B37: Tax % of EBT | C37: =C36/C33 -> 0.24168155 | D37: =D36/D33 -> 0.058413456 | E37: =E36/E33 -> 0.29448047 | F37: =F36/F33 -> 0.32763684 | G37: =G36/G33 -> 0.25863037 | H37: =H36/H33 -> 0.14971777 | I37: =I36/I33 -> 0.30187466 | J37: =J36/J33 -> 0.25329988 | ... L37: =L36/L33 -> 0.2288174
B39: Net Profit | C39: =C33-C36 -> 1099.63 | D39: =D33-D36 -> 2610.85 | E39: =E33-E36 -> 2605.66 | F39: =F33-F36 -> 1316.44 | G39: =G33-G36 -> 1438.65 | H39: =H33-H36 -> 2155.61 | I39: =I33-I36 -> 3809.67 | J39: =J33-J36 -> 4280.1 | ... L39: =L33-L36 -> 5117.56
B40: Net Margin (%) | C40: =C39/C6 -> 0.039859589 | D40: =D39/D6 -> 0.097273612 | E40: =E39/E6 -> 0.087201056 | F40: =F39/F6 -> 0.045182018 | G40: =G39/G6 -> 0.04399096 | H40: =H39/H6 -> 0.050346287 | I40: =I39/I6 -> 0.069129624 | J40: =J39/J6 -> 0.069652996 | ... L40: =L39/L6 -> 0.081974621
B42: No. of Equity Shares | C42: ='Data Sheet'!B93 -> 270.48 | D42: ='Data Sheet'!C93 -> 270.48 | E42: ='Data Sheet'!D93 -> 270.48 | F42: ='Data Sheet'!E93 -> 270.48 | G42: ='Data Sheet'!F93 -> 319.53 | H42: ='Data Sheet'!G93 -> 319.53 | I42: ='Data Sheet'!H93 -> 319.53 | J42: ='Data Sheet'!I93 -> 319.53 | ... L42: ='Data Sheet'!K93 -> 319.53
B44: Price of Share | C44: ='Data Sheet'!B90 -> 90.35 | D44: ='Data Sheet'!C90 -> 79 | E44: ='Data Sheet'!D90 -> 73.8 | F44: ='Data Sheet'!E90 -> 32.85 | G44: ='Data Sheet'!F90 -> 103.25 | H44: ='Data Sheet'!G90 -> 238.65 | I44: ='Data Sheet'!H90 -> 190.25 | J44: ='Data Sheet'!I90 -> 394.2 | ... L44: ='Data Sheet'!K90 -> 378.75
B45: Price Growth% | C45: 0 | D45: =D44/C44-1 -> -0.12562258 | E45: =E44/D44-1 -> -0.065822785 | F45: =F44/E44-1 -> -0.55487805 | G45: =G44/F44-1 -> 2.1430746 | H45: =H44/G44-1 -> 1.3113801 | I45: =I44/H44-1 -> -0.20280746 | J45: =J44/I44-1 -> 1.0720105 | K45: =K44/J44-1 -> -0.047691527 | L45: =L44/K44-1 -> 0.0089238146
B47: Earning per Share | C47: =IFERROR(C39/C42,0) -> 4.0654762 | D47: =IFERROR(D39/D42,0) -> 9.6526545 | E47: =IFERROR(E39/E42,0) -> 9.6334664 | F47: =IFERROR(F39/F42,0) -> 4.8670512 | G47: =IFERROR(G39/G42,0) -> 4.5023941 | H47: =IFERROR(H39/H42,0) -> 6.7461897 | I47: =IFERROR(I39/I42,0) -> 11.92273 | J47: =IFERROR(J39/J42,0) -> 13.394986 | ... L47: =IFERROR(L39/L42,0) -> 16.015898
B48: EPS Growth % | C48: 0 | D48: =D47/C47-1 -> 1.3742986 | E48: =E47/D47-1 -> -0.0019878584 | F48: =F47/E47-1 -> -0.49477676 | G48: =G47/F47-1 -> -0.074923607 | H48: =H47/G47-1 -> 0.4983561 | I48: =I47/H47-1 -> 0.76732804 | J48: =J47/I47-1 -> 0.12348314 | K48: =K47/J47-1 -> 0.11571459 | L48: =L47/K47-1 -> 0.071657275
B50: Dividend | C50: ='Data Sheet'!B31 -> 351.65 | D50: ='Data Sheet'!C31 -> 351.65 | E50: ='Data Sheet'!D31 -> 351.65 | F50: ='Data Sheet'!E31 -> 419.28 | G50: ='Data Sheet'!F31 -> 495.32 | H50: ='Data Sheet'!G31 -> 559.23 | I50: ='Data Sheet'!H31 -> 639.12 | J50: ='Data Sheet'!I31 -> 639.12 | ... L50: ='Data Sheet'!K31 -> 798.9
B51: Dividend per Share | C51: =IFERROR(C50/C42,0) -> 1.3000961 | D51: =IFERROR(D50/D42,0) -> 1.3000961 | E51: =IFERROR(E50/E42,0) -> 1.3000961 | F51: =IFERROR(F50/F42,0) -> 1.5501331 | G51: =IFERROR(G50/G42,0) -> 1.5501518 | H51: =IFERROR(H50/H42,0) -> 1.7501643 | I51: =IFERROR(I50/I42,0) -> 2.0001878 | J51: =IFERROR(J50/J42,0) -> 2.0001878 | ... L51: =IFERROR(L50/L42,0) -> 2.5002347
B52: Dividend payout ratio | C52: =IFERROR(C51/C47,0) -> 0.31978938 | D52: =IFERROR(D51/D47,0) -> 0.13468794 | E52: =IFERROR(E51/E47,0) -> 0.13495621 | F52: =IFERROR(F51/F47,0) -> 0.31849534 | G52: =IFERROR(G51/G47,0) -> 0.344295 | H52: =IFERROR(H51/H47,0) -> 0.25943005 | I52: =IFERROR(I51/I47,0) -> 0.16776256 | J52: =IFERROR(J51/J47,0) -> 0.14932361 | ... L52: =IFERROR(L51/L47,0) -> 0.15610955
B54: Retaioned Earning | C54: =IFERROR(IF(C47>C51,1-C52,0),0) -> 0.68021062 | D54: =IFERROR(IF(D47>D51,1-D52,0),0) -> 0.86531206 | E54: =IFERROR(IF(E47>E51,1-E52,0),0) -> 0.86504379 | F54: =IFERROR(IF(F47>F51,1-F52,0),0) -> 0.68150466 | G54: =IFERROR(IF(G47>G51,1-G52,0),0) -> 0.655705 | H54: =IFERROR(IF(H47>H51,1-H52,0),0) -> 0.74056995 | I54: =IFERROR(IF(I47>I51,1-I52,0),0) -> 0.83223744 | J54: =IFERROR(IF(J47>J51,1-J52,0),0) -> 0.85067639 | ... L54: =IFERROR(IF(L47>L51,1-L52,0),0) -> 0.84389045
A56: # | B56: Balance Sheet
B58: Equity | C58: 270 | D58: 270 | E58: 270 | F58: 270 | G58: 320 | H58: 320 | I58: 320 | J58: 320 | K58: 320 | L58: 320
B59: Reservbes | C59: 12944 | D59: 16130 | E59: 18035 | F59: 19297 | G59: 22003 | H59: 22122 | I59: 28468 | J59: 32037 | K59: 35521 | L59: 39148
...

Sheet Ratio Analysis
B2: ="Historical Financial Statement - "&'Data Sheet'!B1 -> Historical Financial Statement - TATA POWER COMPANY LTD
B3: Year | C3: ='Historical Financial Statements'!C3 -> 42825 | D3: ='Historical Financial Statements'!D3 -> 43190 | E3: ='Historical Financial Statements'!E3 -> 43555 | F3: ='Historical Financial Statements'!F3 -> 43921 | G3: ='Historical Financial Statements'!G3 -> 44286 | H3: ='Historical Financial Statements'!H3 -> 44651 | I3: ='Historical Financial Statements'!I3 -> 45016 | J3: ='Historical Financial Statements'!J3 -> 45382 | ... L3: ='Historical Financial Statements'!L3 -> 46112 | N3: Mean | O3: Median
B5: Sales Growth | D5: =IFERROR('Historical Financial Statements'!D7,0) -> -0.027088992 | E5: =IFERROR('Historical Financial Statements'!E7,0) -> 0.11329208 | F5: =IFERROR('Historical Financial Statements'!F7,0) -> -0.024921807 | G5: =IFERROR('Historical Financial Statements'!G7,0) -> 0.12242225 | H5: =IFERROR('Historical Financial Statements'!H7,0) -> 0.30921518 | I5: =IFERROR('Historical Financial Statements'!I7,0) -> 0.28712408 | J5: =IFERROR('Historical Financial Statements'!J7,0) -> 0.1150413 | K5: =IFERROR('Historical Financial Statements'!K7,0) -> 0.065572207 | L5: =IFERROR('Historical Financial Statements'!L7,0) -> -0.046575015 | N5: =IFERROR(AVERAGE(D5:L5),0) -> 0.10156459 | O5: =IFERROR(MEDIAN(D5:L5),0) -> 0.11329208
B6: EBITDA Growth | D6: =IFERROR('Historical Financial Statements'!D18/'Historical Financial Statements'!C18-1,0) -> 0.060980133 | E6: =IFERROR('Historical Financial Statements'!E18/'Historical Financial Statements'!D18-1,0) -> 0.070160593 | F6: =IFERROR('Historical Financial Statements'!F18/'Historical Financial Statements'!E18-1,0) -> 0.17029359 | G6: =IFERROR('Historical Financial Statements'!G18/'Historical Financial Statements'!F18-1,0) -> -0.11141786 | H6: =IFERROR('Historical Financial Statements'!H18/'Historical Financial Statements'!G18-1,0) -> 0.090633093 | I6: =IFERROR('Historical Financial Statements'!I18/'Historical Financial Statements'!H18-1,0) -> 0.087468072 | J6: =IFERROR('Historical Financial Statements'!J18/'Historical Financial Statements'!I18-1,0) -> 0.3314803 | K6: =IFERROR('Historical Financial Statements'!K18/'Historical Financial Statements'!J18-1,0) -> 0.28033873 | L6: =IFERROR('Historical Financial Statements'!L18/'Historical Financial Statements'!K18-1,0) -> -0.058613914 | N6: =IFERROR(AVERAGE(D6:L6),0) -> 0.10236919 | O6: =IFERROR(MEDIAN(D6:L6),0) -> 0.087468072
B7: EBIT Growth | D7: =IFERROR('Historical Financial Statements'!D24/'Historical Financial Statements'!C24-1,0) -> -0.0046047304 | E7: =IFERROR('Historical Financial Statements'!E24/'Historical Financial Statements'!D24-1,0) -> 0.098729966 | F7: =IFERROR('Historical Financial Statements'!F24/'Historical Financial Statements'!E24-1,0) -> 0.20722632 | G7: =IFERROR('Historical Financial Statements'!G24/'Historical Financial Statements'!F24-1,0) -> -0.18552849 | H7: =IFERROR('Historical Financial Statements'!H24/'Historical Financial Statements'!G24-1,0) -> 0.06175387 | I7: =IFERROR('Historical Financial Statements'!I24/'Historical Financial Statements'!H24-1,0) -> 0.078172634 | J7: =IFERROR('Historical Financial Statements'!J24/'Historical Financial Statements'!I24-1,0) -> 0.48716317 | K7: =IFERROR('Historical Financial Statements'!K24/'Historical Financial Statements'!J24-1,0) -> 0.37685277 | L7: =IFERROR('Historical Financial Statements'!L24/'Historical Financial Statements'!K24-1,0) -> -0.14832786 | N7: =IFERROR(AVERAGE(D7:L7),0) -> 0.10793752 | O7: =IFERROR(MEDIAN(D7:L7),0) -> 0.078172634
B8: Net Profit Growth | D8: =IFERROR('Historical Financial Statements'!D39/'Historical Financial Statements'!C39-1,0) -> 1.3742986 | E8: =IFERROR('Historical Financial Statements'!E39/'Historical Financial Statements'!D39-1,0) -> -0.0019878584 | F8: =IFERROR('Historical Financial Statements'!F39/'Historical Financial Statements'!E39-1,0) -> -0.49477676 | G8: =IFERROR('Historical Financial Statements'!G39/'Historical Financial Statements'!F39-1,0) -> 0.092833703 | H8: =IFERROR('Historical Financial Statements'!H39/'Historical Financial Statements'!G39-1,0) -> 0.4983561 | I8: =IFERROR('Historical Financial Statements'!I39/'Historical Financial Statements'!H39-1,0) -> 0.76732804 | J8: =IFERROR('Historical Financial Statements'!J39/'Historical Financial Statements'!I39-1,0) -> 0.12348314 | K8: =IFERROR('Historical Financial Statements'!K39/'Historical Financial Statements'!J39-1,0) -> 0.11571459 | L8: =IFERROR('Historical Financial Statements'!L39/'Historical Financial Statements'!K39-1,0) -> 0.071657275 | N8: =IFERROR(AVERAGE(D8:L8),0) -> 0.28298965 | O8: =IFERROR(MEDIAN(D8:L8),0) -> 0.11571459
B9: Dividend Growth | D9: ='Historical Financial Statements'!D50/'Historical Financial Statements'!C50-1 -> 0 | E9: ='Historical Financial Statements'!E50/'Historical Financial Statements'!D50-1 -> 0 | F9: ='Historical Financial Statements'!F50/'Historical Financial Statements'!E50-1 -> 0.19232191 | G9: ='Historical Financial Statements'!G50/'Historical Financial Statements'!F50-1 -> 0.18135852 | H9: ='Historical Financial Statements'!H50/'Historical Financial Statements'!G50-1 -> 0.1290277 | I9: ='Historical Financial Statements'!I50/'Historical Financial Statements'!H50-1 -> 0.14285714 | J9: ='Historical Financial Statements'!J50/'Historical Financial Statements'!I50-1 -> 0 | K9: ='Historical Financial Statements'!K50/'Historical Financial Statements'!J50-1 -> 0.125 | L9: ='Historical Financial Statements'!L50/'Historical Financial Statements'!K50-1 -> 0.11111111 | N9: =IFERROR(AVERAGE(D9:L9),0) -> 0.097964043 | O9: =IFERROR(MEDIAN(D9:L9),0) -> 0.125
B11: Gross Margin | C11: =IFERROR('Historical Financial Statements'!C13,0) -> 0.23831476 | D11: =IFERROR('Historical Financial Statements'!D13,0) -> 0.2599061 | E11: =IFERROR('Historical Financial Statements'!E13,0) -> 0.24711607 | F11: =IFERROR('Historical Financial Statements'!F13,0) -> 0.29163722 | G11: =IFERROR('Historical Financial Statements'!G13,0) -> 0.23599049 | H11: =IFERROR('Historical Financial Statements'!H13,0) -> 0.2003075 | I11: =IFERROR('Historical Financial Statements'!I13,0) -> 0.17326328 | J11: =IFERROR('Historical Financial Statements'!J13,0) -> 0.20143778 | ... L11: =IFERROR('Historical Financial Statements'!L13,0) -> 0.23876368 | N11: =IFERROR(AVERAGE(C11:L11),0) -> 0.23249843 | O11: =IFERROR(MEDIAN(C11:L11),0) -> 0.23828108
B12: EBITDA Margin | C12: =IFERROR('Historical Financial Statements'!C19,0) -> 0.22084713 | D12: =IFERROR('Historical Financial Statements'!D19,0) -> 0.24083849 | E12: =IFERROR('Historical Financial Statements'!E19,0) -> 0.23150785 | F12: =IFERROR('Historical Financial Statements'!F19,0) -> 0.27785685 | G12: =IFERROR('Historical Financial Statements'!G19,0) -> 0.21996948 | H12: =IFERROR('Historical Financial Statements'!H19,0) -> 0.18324413 | I12: =IFERROR('Historical Financial Statements'!I19,0) -> 0.15481968 | J12: =IFERROR('Historical Financial Statements'!J19,0) -> 0.18487149 | ... L12: =IFERROR('Historical Financial Statements'!L19,0) -> 0.21932755 | N12: =IFERROR(AVERAGE(C12:L12),0) -> 0.21554151 | O12: =IFERROR(MEDIAN(C12:L12),0) -> 0.2204083
B13: EBIT Margin | C13: =IFERROR('Historical Financial Statements'!C25,0) -> 0.14996054 | D13: =IFERROR('Historical Financial Statements'!D25,0) -> 0.15342618 | E13: =IFERROR('Historical Financial Statements'!E25,0) -> 0.15141933 | F13: =IFERROR('Historical Financial Statements'!F25,0) -> 0.18746948 | G13: =IFERROR('Historical Financial Statements'!G25,0) -> 0.13603485 | H13: =IFERROR('Historical Financial Statements'!H25,0) -> 0.11032223 | I13: =IFERROR('Historical Financial Statements'!I25,0) -> 0.092412539 | J13: =IFERROR('Historical Financial Statements'!J25,0) -> 0.1232533 | ... L13: =IFERROR('Historical Financial Statements'!L25,0) -> 0.14226206 | N13: =IFERROR(AVERAGE(C13:L13),0) -> 0.14058192 | O13: =IFERROR(MEDIAN(C13:L13),0) -> 0.1461113
B14: EBT Margin | C14: =IFERROR('Historical Financial Statements'!C34,0) -> 0.052563127 | D14: =IFERROR('Historical Financial Statements'!D34,0) -> 0.1033082 | E14: =IFERROR('Historical Financial Statements'!E34,0) -> 0.12359836 | F14: =IFERROR('Historical Financial Statements'!F34,0) -> 0.067198831 | G14: =IFERROR('Historical Financial Statements'!G34,0) -> 0.059337419 | H14: =IFERROR('Historical Financial Statements'!H34,0) -> 0.059211265 | I14: =IFERROR('Historical Financial Statements'!I34,0) -> 0.099021795 | J14: =IFERROR('Historical Financial Statements'!J34,0) -> 0.093281084 | ... L14: =IFERROR('Historical Financial Statements'!L34,0) -> 0.10629729 | N14: =IFERROR(AVERAGE(C14:L14),0) -> 0.086033218 | O14: =IFERROR(MEDIAN(C14:L14),0) -> 0.094897948
B15: Net Profit Margin | C15: =IFERROR('Historical Financial Statements'!C40,0) -> 0.039859589 | D15: =IFERROR('Historical Financial Statements'!D40,0) -> 0.097273612 | E15: =IFERROR('Historical Financial Statements'!E40,0) -> 0.087201056 | F15: =IFERROR('Historical Financial Statements'!F40,0) -> 0.045182018 | G15: =IFERROR('Historical Financial Statements'!G40,0) -> 0.04399096 | H15: =IFERROR('Historical Financial Statements'!H40,0) -> 0.050346287 | I15: =IFERROR('Historical Financial Statements'!I40,0) -> 0.069129624 | J15: =IFERROR('Historical Financial Statements'!J40,0) -> 0.069652996 | ... L15: =IFERROR('Historical Financial Statements'!L40,0) -> 0.081974621 | N15: =IFERROR(AVERAGE(C15:L15),0) -> 0.06575414 | O15: =IFERROR(MEDIAN(C15:L15),0) -> 0.06939131
B17: Sales_Expenses % Sales | C17: =IFERROR('Historical Financial Statements'!C16,0) -> 0.017467637 | D17: =IFERROR('Historical Financial Statements'!D16,0) -> 0.019067617 | E17: =IFERROR('Historical Financial Statements'!E16,0) -> 0.015608215 | F17: =IFERROR('Historical Financial Statements'!F16,0) -> 0.013780371 | G17: =IFERROR('Historical Financial Statements'!G16,0) -> 0.016021008 | H17: =IFERROR('Historical Financial Statements'!H16,0) -> 0.017063379 | I17: =IFERROR('Historical Financial Statements'!I16,0) -> 0.018443603 | J17: =IFERROR('Historical Financial Statements'!J16,0) -> 0.016566285 | ... L17: =IFERROR('Historical Financial Statements'!L16,0) -> 0.019436127 | N17: =IFERROR(AVERAGE(C17:L17),0) -> 0.016956921 | O17: =IFERROR(MEDIAN(C17:L17),0) -> 0.016814832
B18: Depreciation % Sales | C18: =IFERROR('Historical Financial Statements'!C22,0) -> 0.070886583 | D18: =IFERROR('Historical Financial Statements'!D22,0) -> 0.08741231 | E18: =IFERROR('Historical Financial Statements'!E22,0) -> 0.080088524 | F18: =IFERROR('Historical Financial Statements'!F22,0) -> 0.090387375 | G18: =IFERROR('Historical Financial Statements'!G22,0) -> 0.083934623 | H18: =IFERROR('Historical Financial Statements'!H22,0) -> 0.0729219 | I18: =IFERROR('Historical Financial Statements'!I22,0) -> 0.062407139 | J18: =IFERROR('Historical Financial Statements'!J22,0) -> 0.06161819 | ... L18: =IFERROR('Historical Financial Statements'!L22,0) -> 0.077065492 | N18: =IFERROR(AVERAGE(C18:L18),0) -> 0.074959585 | O18: =IFERROR(MEDIAN(C18:L18),0) -> 0.074993696
B19: Operating_Income % Sales | C19: =IFERROR('Historical Financial Statements'!C25,0) -> 0.14996054 | D19: =IFERROR('Historical Financial Statements'!D25,0) -> 0.15342618 | E19: =IFERROR('Historical Financial Statements'!E25,0) -> 0.15141933 | F19: =IFERROR('Historical Financial Statements'!F25,0) -> 0.18746948 | G19: =IFERROR('Historical Financial Statements'!G25,0) -> 0.13603485 | H19: =IFERROR('Historical Financial Statements'!H25,0) -> 0.11032223 | I19: =IFERROR('Historical Financial Statements'!I25,0) -> 0.092412539 | J19: =IFERROR('Historical Financial Statements'!J25,0) -> 0.1232533 | ... L19: =IFERROR('Historical Financial Statements'!L25,0) -> 0.14226206 | N19: =IFERROR(AVERAGE(C19:L19),0) -> 0.14058192 | O19: =IFERROR(MEDIAN(C19:L19),0) -> 0.1461113
